2022-10-11 11:46:18|ERROR|http.py|26|281473251607008|Traceback (most recent call last):
  File "/usr/lib/python3/dist-packages/urllib3/connectionpool.py", line 665, in urlopen
    httplib_response = self._make_request(
  File "/usr/lib/python3/dist-packages/urllib3/connectionpool.py", line 376, in _make_request
    self._validate_conn(conn)
  File "/usr/lib/python3/dist-packages/urllib3/connectionpool.py", line 996, in _validate_conn
    conn.connect()
  File "/usr/lib/python3/dist-packages/urllib3/connection.py", line 389, in connect
    cert = self.sock.getpeercert()
  File "/usr/lib/python3.8/ssl.py", line 1123, in getpeercert
    self._check_connected()
  File "/usr/lib/python3.8/ssl.py", line 1088, in _check_connected
    self.getpeername()
OSError: [Errno 107] Transport endpoint is not connected

During handling of the above exception, another exception occurred:

Traceback (most recent call last):
  File "/config/.local/lib/python3.8/site-packages/requests/adapters.py", line 489, in send
    resp = conn.urlopen(
  File "/usr/lib/python3/dist-packages/urllib3/connectionpool.py", line 719, in urlopen
    retries = retries.increment(
  File "/usr/lib/python3/dist-packages/urllib3/util/retry.py", line 400, in increment
    raise six.reraise(type(error), error, _stacktrace)
  File "/usr/lib/python3/dist-packages/six.py", line 702, in reraise
    raise value.with_traceback(tb)
  File "/usr/lib/python3/dist-packages/urllib3/connectionpool.py", line 665, in urlopen
    httplib_response = self._make_request(
  File "/usr/lib/python3/dist-packages/urllib3/connectionpool.py", line 376, in _make_request
    self._validate_conn(conn)
  File "/usr/lib/python3/dist-packages/urllib3/connectionpool.py", line 996, in _validate_conn
    conn.connect()
  File "/usr/lib/python3/dist-packages/urllib3/connection.py", line 389, in connect
    cert = self.sock.getpeercert()
  File "/usr/lib/python3.8/ssl.py", line 1123, in getpeercert
    self._check_connected()
  File "/usr/lib/python3.8/ssl.py", line 1088, in _check_connected
    self.getpeername()
urllib3.exceptions.ProtocolError: ('Connection aborted.', OSError(107, 'Transport endpoint is not connected'))

During handling of the above exception, another exception occurred:

Traceback (most recent call last):
  File "/config/.local/lib/python3.8/site-packages/huobi/utils/http.py", line 22, in get
    res = requests.get(url, params=params, headers=headers)
  File "/config/.local/lib/python3.8/site-packages/requests/api.py", line 73, in get
    return request("get", url, params=params, **kwargs)
  File "/config/.local/lib/python3.8/site-packages/requests/api.py", line 59, in request
    return session.request(method=method, url=url, **kwargs)
  File "/config/.local/lib/python3.8/site-packages/requests/sessions.py", line 587, in request
    resp = self.send(prep, **send_kwargs)
  File "/config/.local/lib/python3.8/site-packages/requests/sessions.py", line 701, in send
    r = adapter.send(request, **kwargs)
  File "/config/.local/lib/python3.8/site-packages/requests/adapters.py", line 547, in send
    raise ConnectionError(err, request=request)
requests.exceptions.ConnectionError: ('Connection aborted.', OSError(107, 'Transport endpoint is not connected'))
||
